<?xml version="1.0" ?>
<!-- =================================================================================== -->
<!-- |    This document was autogenerated by xacro from hexapod.xacro                  | -->
<!-- |    EDITING THIS FILE BY HAND IS NOT RECOMMENDED                                 | -->
<!-- =================================================================================== -->
<robot name="Hexapod">
  <!-- <xacro:arg name="arm_id_1" default="panda_1" /> -->
  <link name="world"/>
  <joint name="world_connect" type="fixed">
    <parent link="world"/>
    <child link="base_link"/>
    <origin rpy="0 0 0" xyz="0 0 0.1"/>
  </joint>
  <link name="base_link"/>
  <!-- <xacro:include filename="$(find franka_description)/robots/panda_gazebo.xacro"/> -->
  <!-- <xacro:include filename="$(find franka_description)/robots/hand.xacro"/> -->
  <!-- <xacro:include filename="$(find realsense_ros_gazebo)/xacro/inertia_calc.xacro"/> -->
  <!-- <xacro:include filename="$(find realsense_ros_gazebo)/xacro/tracker.xacro"/> -->
  <!-- <xacro:include filename="$(find hexapod)/robot/depthcam.xacro"/> -->
  <joint name="j_hexapod_attachment" type="fixed">
    <parent link="base_link"/>
    <child link="MP_BODY"/>
    <origin rpy="0 0 0.0" xyz="0 0 0"/>
    <insert_block name="origin"/>
  </joint>
  <link name="MP_BODY">
    <inertial>
      <origin rpy="0 0 0" xyz="0 0 0.02"/>
      <mass value="0.8"/>
      <!-- <mass value="10.0"/> -->
      <inertia ixx="0.0010867" ixy="0" ixz="0" iyy="0.0010867" iyz="0" izz="0.00196"/>
      <!-- <inertia ixx="31.081800"  ixy="2.5460189"  ixz="20.318174" iyy="63.787776" iyz="1.6417863" izz="53.316425" /> -->
    </inertial>
    <visual>
      <origin rpy="-1.57 0 0" xyz="-0.071 -0.075 0.041"/>
      <geometry>
        <!--box size="0.102 0.109 0.106" /-->
        <mesh filename="package://hexapod/meshes/test4.STL" scale="0.001 0.001 0.001"/>
      </geometry>
      <material name="Grey">
        <color rgba="0.20 0.20 0.20 1.0"/>
      </material>
    </visual>
    <collision>
      <origin rpy="0 0 0" xyz="0 0 0.02"/>
      <geometry>
        <!-- <box size="0.14 0.15 0.1"/> -->
        <cylinder length="0.04" radius="0.07"/>
      </geometry>
    </collision>
  </link>
  <gazebo reference="MP_BODY">
    <material>Gazebo/Grey</material>
  </gazebo>
  <link name="c1_rf">
    <inertial>
      <origin rpy="0 0 0" xyz="0 0 0"/>
      <mass value="0.024357719"/>
      <inertia ixx="0.0051411124" ixy="-0.00057530255" ixz="-0.000024729049" iyy="0.0081915737" iyz="-0.000019223094" izz="0.0011379812"/>
    </inertial>
    <visual>
      <origin rpy="0 0 0" xyz="0 0.012 0"/>
      <geometry>
        <!--box size="0.045 0.022 0.0325" /-->
        <mesh filename="package://hexapod/meshes/right1_Link.STL" scale="1 1 1"/>
      </geometry>
      <material name="Grey">
        <color rgba="0.20 0.20 0.20 1.0"/>
      </material>
    </visual>
    <collision>
      <!-- <origin xyz="0 0.012 0" rpy="0 0 0"  />
      <geometry>
        <mesh filename="package://hexapod/meshes/right1_Link.STL"  scale="1 1 1"/>
      </geometry> -->
      <origin rpy="1.57 0 0" xyz="0 0.0 0"/>
      <geometry>
        <cylinder length="0.03" radius="0.01"/>
      </geometry>
    </collision>
  </link>
  <link name="connect_rf">
    <origin rpy="0 0 0" xyz="0 0 0"/>
    <inertial>
      <origin xyz="0 0 0"/>
      <mass value="0.97559947"/>
      <inertia ixx="3.1081800" ixy="-0.25460189" ixz="2.0318174" iyy="6.3787776" iyz="0.16417863" izz="5.3316425"/>
    </inertial>
  </link>
  <joint name="j_connect_rf" type="fixed">
    <parent link="MP_BODY"/>
    <child link="connect_rf"/>
    <origin rpy="0 3.141592653589793 -1.5707963267948966" xyz="0.038 0.046 0.02"/>
  </joint>
  <link name="thigh_rf">
    <inertial>
      <origin rpy="0 1.57 0" xyz="0 0.0 0"/>
      <mass value="0.024357719"/>
      <inertia ixx="0.0051411124" ixy="-0.00057530255" ixz="-0.000024729049" iyy="0.0081915737" iyz="-0.000019223094" izz="0.0011379812"/>
    </inertial>
    <visual>
      <origin rpy="0 0 0" xyz="0 0 -0.004"/>
      <geometry>
        <!--box size="0.045 0.022 0.0325" /-->
        <mesh filename="package://hexapod/meshes/LinkThigh.STL" scale="1 1 1"/>
      </geometry>
      <material name="Grey">
        <color rgba="0.20 0.20 0.20 1.0"/>
      </material>
    </visual>
    <collision>
      <origin rpy="0 1.57 0" xyz="0 0.0 0"/>
      <geometry>
        <cylinder length="0.05" radius="0.01"/>
      </geometry>
    </collision>
  </link>
  <link name="tibia_rf">
    <inertial>
      <origin rpy="0 1.57 0.524" xyz="-0.027 -0.017 0"/>
      <mass value="0.002"/>
      <inertia ixx="0.0000024045" ixy="0" ixz="0" iyy="0.0000024045" iyz="0" izz="0.000000009"/>
    </inertial>
    <visual>
      <origin rpy="0 0 0" xyz="0 0 0"/>
      <geometry>
        <!--box size="0.045 0.022 0.0325" /-->
        <!-- <mesh filename="package://robot_envs/hexapod/robot/meshes/LinkTibia.STL"  scale="1 1 1"/> -->
        <mesh filename="package://hexapod/meshes/NewTibia.STL" scale="0.001 0.001 0.001"/>
      </geometry>
      <material name="Grey">
        <color rgba="0.20 0.20 0.20 1.0"/>
      </material>
    </visual>
    <collision>
      <origin rpy="0 1.57 0.524" xyz="-0.027 -0.017 0"/>
      <geometry>
        <cylinder length="0.12" radius="0.003"/>
      </geometry>
    </collision>
  </link>
  <!-- <link name="tibia_e_${suffix}">

      <visual><geometry><sphere radius="0.003"/></geometry></visual>
      <collision><geometry><sphere radius="0.005"/></geometry></collision>
      <inertial>
          <origin xyz="0 0 0" rpy="0 0 0"/>
          <mass value="0.001"/>
          <inertia ixx="0.1" ixy="0.0" ixz="0.0" iyy="0.1"  iyz="0.0" izz="0.1"/>
      </inertial>
  </link> -->
  <link name="tibia_e_rf">
    <visual>
      <origin rpy="0 0 0" xyz="0 0 0"/>
      <geometry>
        <sphere radius=".006"/>
      </geometry>
    </visual>
    <collision>
      <geometry>
        <sphere radius=".006"/>
      </geometry>
    </collision>
    <inertial>
      <origin rpy="0 0 0" xyz="0 0 0"/>
      <mass value="0.01"/>
      <inertia ixx="0.00144" ixy="0.0" ixz="0.0" iyy="0.00144" iyz="0.0" izz="0.00144"/>
    </inertial>
  </link>
  <!-- here are an edit including a ball joint -->
  <joint name="j_c1_rf" type="revolute">
    <parent link="connect_rf"/>
    <child link="c1_rf"/>
    <origin rpy="0 3.141592653589793 -1.0471975511965976" xyz="0 0 0"/>
    <axis xyz="0 0 -1"/>
    <limit effort="5.8" lower="-2.6179939" upper="2.6179939" velocity="10"/>
    <dynamics damping="0.5" friction="0.0"/>
  </joint>
  <joint name="j_thigh_rf" type="revolute">
    <parent link="c1_rf"/>
    <child link="thigh_rf"/>
    <origin rpy="1.5707963267948966 -0.2617993877991494 1.5707963267948966" xyz="0 0.053 0"/>
    <axis xyz="0 0 1"/>
    <limit effort="5.8" lower="-2.6179939" upper="2.6179939" velocity="10"/>
    <dynamics damping="0.5" friction="0.0"/>
  </joint>
  <joint name="j_tibia_rf" type="revolute">
    <parent link="thigh_rf"/>
    <child link="tibia_rf"/>
    <!-- <origin xyz="0 ${thigh_offset_y} ${thigh_offset_z}" rpy="-1.5707 0 3.14159" /> -->
    <origin rpy="3.141592653589793 0 2.0943951023931953" xyz="0.0525 0 0"/>
    <axis xyz="0 0 -1"/>
    <limit effort="5.8" lower="-2.5" upper="2.5" velocity="10"/>
    <dynamics damping="0.5" friction="0.0"/>
  </joint>
  <joint name="j_tibia_e_rf" type="fixed">
    <parent link="tibia_rf"/>
    <child link="tibia_e_rf"/>
    <!-- <origin xyz="0 ${thigh_offset_y} ${thigh_offset_z}" rpy="-1.5707 0 3.14159" /> -->
    <origin rpy="0 0 0" xyz="-0.084 -0.05 0"/>
  </joint>
  <transmission name="t_c1_rf">
    <type>transmission_interface/SimpleTransmission</type>
    <joint name="j_c1_rf">
      <hardwareInterface>hardware_interface/EffortJointInterface</hardwareInterface>
    </joint>
    <actuator name="m_c1_rf">
      <hardwareInterface>hardware_interface/EffortJointInterface</hardwareInterface>
      <mechanicalReduction>1</mechanicalReduction>
    </actuator>
  </transmission>
  <transmission name="t_thigh_rf">
    <type>transmission_interface/SimpleTransmission</type>
    <joint name="j_thigh_rf">
      <hardwareInterface>hardware_interface/EffortJointInterface</hardwareInterface>
    </joint>
    <actuator name="m_thigh_rf">
      <hardwareInterface>hardware_interface/EffortJointInterface</hardwareInterface>
      <mechanicalReduction>1</mechanicalReduction>
    </actuator>
  </transmission>
  <transmission name="t_tibia_rf">
    <type>transmission_interface/SimpleTransmission</type>
    <joint name="j_tibia_rf">
      <hardwareInterface>hardware_interface/EffortJointInterface</hardwareInterface>
    </joint>
    <actuator name="m_tibia_rf">
      <hardwareInterface>hardware_interface/EffortJointInterface</hardwareInterface>
      <mechanicalReduction>1</mechanicalReduction>
    </actuator>
  </transmission>
  <gazebo reference="MP_BODY">
    <mu1>0.61</mu1>
    <mu2>0.61</mu2>
  </gazebo>
  <gazebo reference="c1_rf">
    <material>Gazebo/Grey</material>
    <mu1>0.61</mu1>
    <mu2>0.61</mu2>
  </gazebo>
  <gazebo reference="connect_rf">
    <mu1>0.61</mu1>
    <mu2>0.61</mu2>
  </gazebo>
  <gazebo reference="thigh_rf">
    <material>Gazebo/Grey</material>
    <mu1>0.61</mu1>
    <mu2>0.61</mu2>
  </gazebo>
  <gazebo reference="tibia_rf">
    <material>Gazebo/Grey</material>
    <mu1>0.61</mu1>
    <mu2>0.61</mu2>
  </gazebo>
  <gazebo reference="tibia_e_rf">
    <material>Gazebo/Grey</material>
    <mu1>10</mu1>
    <mu2>10</mu2>
    <kp>1000000.0</kp>
    <kd>10.0</kd>
  </gazebo>
  <!-- <gazebo reference="theta_link_${suffix}">    
    <material>Gazebo/Grey</material>
   <mu1>0.61</mu1>
    <mu2>0.61</mu2>

  </gazebo> -->
  <!-- <gazebo reference="foot_link_${suffix}">    
    <material>Gazebo/Grey</material>
    <mu1>100</mu1>
    <mu2>100</mu2>

    <kp>1000000.0</kp>
    <kd>10.0</kd>

  </gazebo> -->
  <!-- <gazebo reference="footc_${suffix}">    
    <material>Gazebo/White</material>
  </gazebo> -->
  <link name="c1_rm">
    <inertial>
      <origin rpy="0 0 0" xyz="0 0 0"/>
      <mass value="0.024357719"/>
      <inertia ixx="0.0051411124" ixy="-0.00057530255" ixz="-0.000024729049" iyy="0.0081915737" iyz="-0.000019223094" izz="0.0011379812"/>
    </inertial>
    <visual>
      <origin rpy="0 0 0" xyz="0 0.012 0"/>
      <geometry>
        <!--box size="0.045 0.022 0.0325" /-->
        <mesh filename="package://hexapod/meshes/right1_Link.STL" scale="1 1 1"/>
      </geometry>
      <material name="Grey">
        <color rgba="0.20 0.20 0.20 1.0"/>
      </material>
    </visual>
    <collision>
      <!-- <origin xyz="0 0.012 0" rpy="0 0 0"  />
      <geometry>
        <mesh filename="package://hexapod/meshes/right1_Link.STL"  scale="1 1 1"/>
      </geometry> -->
      <origin rpy="1.57 0 0" xyz="0 0.0 0"/>
      <geometry>
        <cylinder length="0.03" radius="0.01"/>
      </geometry>
    </collision>
  </link>
  <link name="connect_rm">
    <origin rpy="0 0 0" xyz="0 0 0"/>
    <inertial>
      <origin xyz="0 0 0"/>
      <mass value="0.97559947"/>
      <inertia ixx="3.1081800" ixy="-0.25460189" ixz="2.0318174" iyy="6.3787776" iyz="0.16417863" izz="5.3316425"/>
    </inertial>
  </link>
  <joint name="j_connect_rm" type="fixed">
    <parent link="MP_BODY"/>
    <child link="connect_rm"/>
    <origin rpy="0 3.141592653589793 -1.5707963267948966" xyz="0.038 0.0  0.02"/>
  </joint>
  <link name="thigh_rm">
    <inertial>
      <origin rpy="0 1.57 0" xyz="0 0.0 0"/>
      <mass value="0.024357719"/>
      <inertia ixx="0.0051411124" ixy="-0.00057530255" ixz="-0.000024729049" iyy="0.0081915737" iyz="-0.000019223094" izz="0.0011379812"/>
    </inertial>
    <visual>
      <origin rpy="0 0 0" xyz="0 0 -0.004"/>
      <geometry>
        <!--box size="0.045 0.022 0.0325" /-->
        <mesh filename="package://hexapod/meshes/LinkThigh.STL" scale="1 1 1"/>
      </geometry>
      <material name="Grey">
        <color rgba="0.20 0.20 0.20 1.0"/>
      </material>
    </visual>
    <collision>
      <origin rpy="0 1.57 0" xyz="0 0.0 0"/>
      <geometry>
        <cylinder length="0.05" radius="0.01"/>
      </geometry>
    </collision>
  </link>
  <link name="tibia_rm">
    <inertial>
      <origin rpy="0 1.57 0.524" xyz="-0.027 -0.017 0"/>
      <mass value="0.002"/>
      <inertia ixx="0.0000024045" ixy="0" ixz="0" iyy="0.0000024045" iyz="0" izz="0.000000009"/>
    </inertial>
    <visual>
      <origin rpy="0 0 0" xyz="0 0 0"/>
      <geometry>
        <!--box size="0.045 0.022 0.0325" /-->
        <!-- <mesh filename="package://robot_envs/hexapod/robot/meshes/LinkTibia.STL"  scale="1 1 1"/> -->
        <mesh filename="package://hexapod/meshes/NewTibia.STL" scale="0.001 0.001 0.001"/>
      </geometry>
      <material name="Grey">
        <color rgba="0.20 0.20 0.20 1.0"/>
      </material>
    </visual>
    <collision>
      <origin rpy="0 1.57 0.524" xyz="-0.027 -0.017 0"/>
      <geometry>
        <cylinder length="0.12" radius="0.003"/>
      </geometry>
    </collision>
  </link>
  <!-- <link name="tibia_e_${suffix}">

      <visual><geometry><sphere radius="0.003"/></geometry></visual>
      <collision><geometry><sphere radius="0.005"/></geometry></collision>
      <inertial>
          <origin xyz="0 0 0" rpy="0 0 0"/>
          <mass value="0.001"/>
          <inertia ixx="0.1" ixy="0.0" ixz="0.0" iyy="0.1"  iyz="0.0" izz="0.1"/>
      </inertial>
  </link> -->
  <link name="tibia_e_rm">
    <visual>
      <origin rpy="0 0 0" xyz="0 0 0"/>
      <geometry>
        <sphere radius=".006"/>
      </geometry>
    </visual>
    <collision>
      <geometry>
        <sphere radius=".006"/>
      </geometry>
    </collision>
    <inertial>
      <origin rpy="0 0 0" xyz="0 0 0"/>
      <mass value="0.01"/>
      <inertia ixx="0.00144" ixy="0.0" ixz="0.0" iyy="0.00144" iyz="0.0" izz="0.00144"/>
    </inertial>
  </link>
  <!-- here are an edit including a ball joint -->
  <joint name="j_c1_rm" type="revolute">
    <parent link="connect_rm"/>
    <child link="c1_rm"/>
    <origin rpy="0 3.141592653589793 0" xyz="0 0 0"/>
    <axis xyz="0 0 -1"/>
    <limit effort="5.8" lower="-2.6179939" upper="2.6179939" velocity="10"/>
    <dynamics damping="0.5" friction="0.0"/>
  </joint>
  <joint name="j_thigh_rm" type="revolute">
    <parent link="c1_rm"/>
    <child link="thigh_rm"/>
    <origin rpy="1.5707963267948966 -0.2617993877991494 1.5707963267948966" xyz="0 0.053 0"/>
    <axis xyz="0 0 1"/>
    <limit effort="5.8" lower="-2.6179939" upper="2.6179939" velocity="10"/>
    <dynamics damping="0.5" friction="0.0"/>
  </joint>
  <joint name="j_tibia_rm" type="revolute">
    <parent link="thigh_rm"/>
    <child link="tibia_rm"/>
    <!-- <origin xyz="0 ${thigh_offset_y} ${thigh_offset_z}" rpy="-1.5707 0 3.14159" /> -->
    <origin rpy="3.141592653589793 0 2.0943951023931953" xyz="0.0525 0 0"/>
    <axis xyz="0 0 -1"/>
    <limit effort="5.8" lower="-2.5" upper="2.5" velocity="10"/>
    <dynamics damping="0.5" friction="0.0"/>
  </joint>
  <joint name="j_tibia_e_rm" type="fixed">
    <parent link="tibia_rm"/>
    <child link="tibia_e_rm"/>
    <!-- <origin xyz="0 ${thigh_offset_y} ${thigh_offset_z}" rpy="-1.5707 0 3.14159" /> -->
    <origin rpy="0 0 0" xyz="-0.084 -0.05 0"/>
  </joint>
  <transmission name="t_c1_rm">
    <type>transmission_interface/SimpleTransmission</type>
    <joint name="j_c1_rm">
      <hardwareInterface>hardware_interface/EffortJointInterface</hardwareInterface>
    </joint>
    <actuator name="m_c1_rm">
      <hardwareInterface>hardware_interface/EffortJointInterface</hardwareInterface>
      <mechanicalReduction>1</mechanicalReduction>
    </actuator>
  </transmission>
  <transmission name="t_thigh_rm">
    <type>transmission_interface/SimpleTransmission</type>
    <joint name="j_thigh_rm">
      <hardwareInterface>hardware_interface/EffortJointInterface</hardwareInterface>
    </joint>
    <actuator name="m_thigh_rm">
      <hardwareInterface>hardware_interface/EffortJointInterface</hardwareInterface>
      <mechanicalReduction>1</mechanicalReduction>
    </actuator>
  </transmission>
  <transmission name="t_tibia_rm">
    <type>transmission_interface/SimpleTransmission</type>
    <joint name="j_tibia_rm">
      <hardwareInterface>hardware_interface/EffortJointInterface</hardwareInterface>
    </joint>
    <actuator name="m_tibia_rm">
      <hardwareInterface>hardware_interface/EffortJointInterface</hardwareInterface>
      <mechanicalReduction>1</mechanicalReduction>
    </actuator>
  </transmission>
  <gazebo reference="MP_BODY">
    <mu1>0.61</mu1>
    <mu2>0.61</mu2>
  </gazebo>
  <gazebo reference="c1_rm">
    <material>Gazebo/Grey</material>
    <mu1>0.61</mu1>
    <mu2>0.61</mu2>
  </gazebo>
  <gazebo reference="connect_rm">
    <mu1>0.61</mu1>
    <mu2>0.61</mu2>
  </gazebo>
  <gazebo reference="thigh_rm">
    <material>Gazebo/Grey</material>
    <mu1>0.61</mu1>
    <mu2>0.61</mu2>
  </gazebo>
  <gazebo reference="tibia_rm">
    <material>Gazebo/Grey</material>
    <mu1>0.61</mu1>
    <mu2>0.61</mu2>
  </gazebo>
  <gazebo reference="tibia_e_rm">
    <material>Gazebo/Grey</material>
    <mu1>10</mu1>
    <mu2>10</mu2>
    <kp>1000000.0</kp>
    <kd>10.0</kd>
  </gazebo>
  <!-- <gazebo reference="theta_link_${suffix}">    
    <material>Gazebo/Grey</material>
   <mu1>0.61</mu1>
    <mu2>0.61</mu2>

  </gazebo> -->
  <!-- <gazebo reference="foot_link_${suffix}">    
    <material>Gazebo/Grey</material>
    <mu1>100</mu1>
    <mu2>100</mu2>

    <kp>1000000.0</kp>
    <kd>10.0</kd>

  </gazebo> -->
  <!-- <gazebo reference="footc_${suffix}">    
    <material>Gazebo/White</material>
  </gazebo> -->
  <link name="c1_rr">
    <inertial>
      <origin rpy="0 0 0" xyz="0 0 0"/>
      <mass value="0.024357719"/>
      <inertia ixx="0.0051411124" ixy="-0.00057530255" ixz="-0.000024729049" iyy="0.0081915737" iyz="-0.000019223094" izz="0.0011379812"/>
    </inertial>
    <visual>
      <origin rpy="0 0 0" xyz="0 0.012 0"/>
      <geometry>
        <!--box size="0.045 0.022 0.0325" /-->
        <mesh filename="package://hexapod/meshes/right1_Link.STL" scale="1 1 1"/>
      </geometry>
      <material name="Grey">
        <color rgba="0.20 0.20 0.20 1.0"/>
      </material>
    </visual>
    <collision>
      <!-- <origin xyz="0 0.012 0" rpy="0 0 0"  />
      <geometry>
        <mesh filename="package://hexapod/meshes/right1_Link.STL"  scale="1 1 1"/>
      </geometry> -->
      <origin rpy="1.57 0 0" xyz="0 0.0 0"/>
      <geometry>
        <cylinder length="0.03" radius="0.01"/>
      </geometry>
    </collision>
  </link>
  <link name="connect_rr">
    <origin rpy="0 0 0" xyz="0 0 0"/>
    <inertial>
      <origin xyz="0 0 0"/>
      <mass value="0.97559947"/>
      <inertia ixx="3.1081800" ixy="-0.25460189" ixz="2.0318174" iyy="6.3787776" iyz="0.16417863" izz="5.3316425"/>
    </inertial>
  </link>
  <joint name="j_connect_rr" type="fixed">
    <parent link="MP_BODY"/>
    <child link="connect_rr"/>
    <origin rpy="0 3.141592653589793 -1.5707963267948966" xyz="0.038 -0.046  0.02"/>
  </joint>
  <link name="thigh_rr">
    <inertial>
      <origin rpy="0 1.57 0" xyz="0 0.0 0"/>
      <mass value="0.024357719"/>
      <inertia ixx="0.0051411124" ixy="-0.00057530255" ixz="-0.000024729049" iyy="0.0081915737" iyz="-0.000019223094" izz="0.0011379812"/>
    </inertial>
    <visual>
      <origin rpy="0 0 0" xyz="0 0 -0.004"/>
      <geometry>
        <!--box size="0.045 0.022 0.0325" /-->
        <mesh filename="package://hexapod/meshes/LinkThigh.STL" scale="1 1 1"/>
      </geometry>
      <material name="Grey">
        <color rgba="0.20 0.20 0.20 1.0"/>
      </material>
    </visual>
    <collision>
      <origin rpy="0 1.57 0" xyz="0 0.0 0"/>
      <geometry>
        <cylinder length="0.05" radius="0.01"/>
      </geometry>
    </collision>
  </link>
  <link name="tibia_rr">
    <inertial>
      <origin rpy="0 1.57 0.524" xyz="-0.027 -0.017 0"/>
      <mass value="0.002"/>
      <inertia ixx="0.0000024045" ixy="0" ixz="0" iyy="0.0000024045" iyz="0" izz="0.000000009"/>
    </inertial>
    <visual>
      <origin rpy="0 0 0" xyz="0 0 0"/>
      <geometry>
        <!--box size="0.045 0.022 0.0325" /-->
        <!-- <mesh filename="package://robot_envs/hexapod/robot/meshes/LinkTibia.STL"  scale="1 1 1"/> -->
        <mesh filename="package://hexapod/meshes/NewTibia.STL" scale="0.001 0.001 0.001"/>
      </geometry>
      <material name="Grey">
        <color rgba="0.20 0.20 0.20 1.0"/>
      </material>
    </visual>
    <collision>
      <origin rpy="0 1.57 0.524" xyz="-0.027 -0.017 0"/>
      <geometry>
        <cylinder length="0.12" radius="0.003"/>
      </geometry>
    </collision>
  </link>
  <!-- <link name="tibia_e_${suffix}">

      <visual><geometry><sphere radius="0.003"/></geometry></visual>
      <collision><geometry><sphere radius="0.005"/></geometry></collision>
      <inertial>
          <origin xyz="0 0 0" rpy="0 0 0"/>
          <mass value="0.001"/>
          <inertia ixx="0.1" ixy="0.0" ixz="0.0" iyy="0.1"  iyz="0.0" izz="0.1"/>
      </inertial>
  </link> -->
  <link name="tibia_e_rr">
    <visual>
      <origin rpy="0 0 0" xyz="0 0 0"/>
      <geometry>
        <sphere radius=".006"/>
      </geometry>
    </visual>
    <collision>
      <geometry>
        <sphere radius=".006"/>
      </geometry>
    </collision>
    <inertial>
      <origin rpy="0 0 0" xyz="0 0 0"/>
      <mass value="0.01"/>
      <inertia ixx="0.00144" ixy="0.0" ixz="0.0" iyy="0.00144" iyz="0.0" izz="0.00144"/>
    </inertial>
  </link>
  <!-- here are an edit including a ball joint -->
  <joint name="j_c1_rr" type="revolute">
    <parent link="connect_rr"/>
    <child link="c1_rr"/>
    <origin rpy="0 3.141592653589793 1.0471975511965976" xyz="0 0 0"/>
    <axis xyz="0 0 -1"/>
    <limit effort="5.8" lower="-2.6179939" upper="2.6179939" velocity="10"/>
    <dynamics damping="0.5" friction="0.0"/>
  </joint>
  <joint name="j_thigh_rr" type="revolute">
    <parent link="c1_rr"/>
    <child link="thigh_rr"/>
    <origin rpy="1.5707963267948966 -0.2617993877991494 1.5707963267948966" xyz="0 0.053 0"/>
    <axis xyz="0 0 1"/>
    <limit effort="5.8" lower="-2.6179939" upper="2.6179939" velocity="10"/>
    <dynamics damping="0.5" friction="0.0"/>
  </joint>
  <joint name="j_tibia_rr" type="revolute">
    <parent link="thigh_rr"/>
    <child link="tibia_rr"/>
    <!-- <origin xyz="0 ${thigh_offset_y} ${thigh_offset_z}" rpy="-1.5707 0 3.14159" /> -->
    <origin rpy="3.141592653589793 0 2.0943951023931953" xyz="0.0525 0 0"/>
    <axis xyz="0 0 -1"/>
    <limit effort="5.8" lower="-2.5" upper="2.5" velocity="10"/>
    <dynamics damping="0.5" friction="0.0"/>
  </joint>
  <joint name="j_tibia_e_rr" type="fixed">
    <parent link="tibia_rr"/>
    <child link="tibia_e_rr"/>
    <!-- <origin xyz="0 ${thigh_offset_y} ${thigh_offset_z}" rpy="-1.5707 0 3.14159" /> -->
    <origin rpy="0 0 0" xyz="-0.084 -0.05 0"/>
  </joint>
  <transmission name="t_c1_rr">
    <type>transmission_interface/SimpleTransmission</type>
    <joint name="j_c1_rr">
      <hardwareInterface>hardware_interface/EffortJointInterface</hardwareInterface>
    </joint>
    <actuator name="m_c1_rr">
      <hardwareInterface>hardware_interface/EffortJointInterface</hardwareInterface>
      <mechanicalReduction>1</mechanicalReduction>
    </actuator>
  </transmission>
  <transmission name="t_thigh_rr">
    <type>transmission_interface/SimpleTransmission</type>
    <joint name="j_thigh_rr">
      <hardwareInterface>hardware_interface/EffortJointInterface</hardwareInterface>
    </joint>
    <actuator name="m_thigh_rr">
      <hardwareInterface>hardware_interface/EffortJointInterface</hardwareInterface>
      <mechanicalReduction>1</mechanicalReduction>
    </actuator>
  </transmission>
  <transmission name="t_tibia_rr">
    <type>transmission_interface/SimpleTransmission</type>
    <joint name="j_tibia_rr">
      <hardwareInterface>hardware_interface/EffortJointInterface</hardwareInterface>
    </joint>
    <actuator name="m_tibia_rr">
      <hardwareInterface>hardware_interface/EffortJointInterface</hardwareInterface>
      <mechanicalReduction>1</mechanicalReduction>
    </actuator>
  </transmission>
  <gazebo reference="MP_BODY">
    <mu1>0.61</mu1>
    <mu2>0.61</mu2>
  </gazebo>
  <gazebo reference="c1_rr">
    <material>Gazebo/Grey</material>
    <mu1>0.61</mu1>
    <mu2>0.61</mu2>
  </gazebo>
  <gazebo reference="connect_rr">
    <mu1>0.61</mu1>
    <mu2>0.61</mu2>
  </gazebo>
  <gazebo reference="thigh_rr">
    <material>Gazebo/Grey</material>
    <mu1>0.61</mu1>
    <mu2>0.61</mu2>
  </gazebo>
  <gazebo reference="tibia_rr">
    <material>Gazebo/Grey</material>
    <mu1>0.61</mu1>
    <mu2>0.61</mu2>
  </gazebo>
  <gazebo reference="tibia_e_rr">
    <material>Gazebo/Grey</material>
    <mu1>10</mu1>
    <mu2>10</mu2>
    <kp>1000000.0</kp>
    <kd>10.0</kd>
  </gazebo>
  <!-- <gazebo reference="theta_link_${suffix}">    
    <material>Gazebo/Grey</material>
   <mu1>0.61</mu1>
    <mu2>0.61</mu2>

  </gazebo> -->
  <!-- <gazebo reference="foot_link_${suffix}">    
    <material>Gazebo/Grey</material>
    <mu1>100</mu1>
    <mu2>100</mu2>

    <kp>1000000.0</kp>
    <kd>10.0</kd>

  </gazebo> -->
  <!-- <gazebo reference="footc_${suffix}">    
    <material>Gazebo/White</material>
  </gazebo> -->
  <link name="c1_lf">
    <inertial>
      <origin rpy="0 0 0" xyz="0 0 0"/>
      <mass value="0.024357719"/>
      <inertia ixx="0.0051411124" ixy="-0.00057530255" ixz="-0.000024729049" iyy="0.0081915737" iyz="-0.000019223094" izz="0.0011379812"/>
    </inertial>
    <visual>
      <origin rpy="0 0 0" xyz="0 0.012 0"/>
      <geometry>
        <!--box size="0.045 0.022 0.0325" /-->
        <mesh filename="package://hexapod/meshes/right1_Link.STL" scale="1 1 1"/>
      </geometry>
      <material name="Grey">
        <color rgba="0.20 0.20 0.20 1.0"/>
      </material>
    </visual>
    <collision>
      <!-- <origin xyz="0 0.012 0" rpy="0 0 0"  />
      <geometry>
        <mesh filename="package://hexapod/meshes/right1_Link.STL"  scale="1 1 1"/>
      </geometry> -->
      <origin rpy="1.57 0 0" xyz="0 0.0 0"/>
      <geometry>
        <cylinder length="0.03" radius="0.01"/>
      </geometry>
    </collision>
  </link>
  <link name="connect_lf">
    <origin rpy="0 0 0" xyz="0 0 0"/>
    <inertial>
      <origin xyz="0 0 0"/>
      <mass value="0.97559947"/>
      <inertia ixx="3.1081800" ixy="-0.25460189" ixz="2.0318174" iyy="6.3787776" iyz="0.16417863" izz="5.3316425"/>
    </inertial>
  </link>
  <joint name="j_connect_lf" type="fixed">
    <parent link="MP_BODY"/>
    <child link="connect_lf"/>
    <origin rpy="0 -3.141592653589793 4.71238898038469" xyz="-0.038 0.046  0.02"/>
  </joint>
  <link name="thigh_lf">
    <inertial>
      <origin rpy="0 1.57 0" xyz="0 0.0 0"/>
      <mass value="0.024357719"/>
      <inertia ixx="0.0051411124" ixy="-0.00057530255" ixz="-0.000024729049" iyy="0.0081915737" iyz="-0.000019223094" izz="0.0011379812"/>
    </inertial>
    <visual>
      <origin rpy="0 0 0" xyz="0 0 -0.004"/>
      <geometry>
        <!--box size="0.045 0.022 0.0325" /-->
        <mesh filename="package://hexapod/meshes/LinkThigh.STL" scale="1 1 1"/>
      </geometry>
      <material name="Grey">
        <color rgba="0.20 0.20 0.20 1.0"/>
      </material>
    </visual>
    <collision>
      <origin rpy="0 1.57 0" xyz="0 0.0 0"/>
      <geometry>
        <cylinder length="0.05" radius="0.01"/>
      </geometry>
    </collision>
  </link>
  <link name="tibia_lf">
    <inertial>
      <origin rpy="0 1.57 0.524" xyz="-0.027 -0.017 0"/>
      <mass value="0.002"/>
      <inertia ixx="0.0000024045" ixy="0" ixz="0" iyy="0.0000024045" iyz="0" izz="0.000000009"/>
    </inertial>
    <visual>
      <origin rpy="0 0 0" xyz="0 0 0"/>
      <geometry>
        <!--box size="0.045 0.022 0.0325" /-->
        <!-- <mesh filename="package://robot_envs/hexapod/robot/meshes/LinkTibia.STL"  scale="1 1 1"/> -->
        <mesh filename="package://hexapod/meshes/NewTibia.STL" scale="0.001 0.001 0.001"/>
      </geometry>
      <material name="Grey">
        <color rgba="0.20 0.20 0.20 1.0"/>
      </material>
    </visual>
    <collision>
      <origin rpy="0 1.57 0.524" xyz="-0.027 -0.017 0"/>
      <geometry>
        <cylinder length="0.12" radius="0.003"/>
      </geometry>
    </collision>
  </link>
  <!-- <link name="tibia_e_${suffix}">

      <visual><geometry><sphere radius="0.003"/></geometry></visual>
      <collision><geometry><sphere radius="0.005"/></geometry></collision>
      <inertial>
          <origin xyz="0 0 0" rpy="0 0 0"/>
          <mass value="0.001"/>
          <inertia ixx="0.1" ixy="0.0" ixz="0.0" iyy="0.1"  iyz="0.0" izz="0.1"/>
      </inertial>
  </link> -->
  <link name="tibia_e_lf">
    <visual>
      <origin rpy="0 0 0" xyz="0 0 0"/>
      <geometry>
        <sphere radius=".006"/>
      </geometry>
    </visual>
    <collision>
      <geometry>
        <sphere radius=".006"/>
      </geometry>
    </collision>
    <inertial>
      <origin rpy="0 0 0" xyz="0 0 0"/>
      <mass value="0.01"/>
      <inertia ixx="0.00144" ixy="0.0" ixz="0.0" iyy="0.00144" iyz="0.0" izz="0.00144"/>
    </inertial>
  </link>
  <!-- here are an edit including a ball joint -->
  <joint name="j_c1_lf" type="revolute">
    <parent link="connect_lf"/>
    <child link="c1_lf"/>
    <origin rpy="0 3.141592653589793 4.1887902047863905" xyz="0 0 0"/>
    <axis xyz="0 0 -1"/>
    <limit effort="5.8" lower="-2.6179939" upper="2.6179939" velocity="10"/>
    <dynamics damping="0.5" friction="0.0"/>
  </joint>
  <joint name="j_thigh_lf" type="revolute">
    <parent link="c1_lf"/>
    <child link="thigh_lf"/>
    <origin rpy="1.5707963267948966 -0.2617993877991494 1.5707963267948966" xyz="0 0.053 0"/>
    <axis xyz="0 0 1"/>
    <limit effort="5.8" lower="-2.6179939" upper="2.6179939" velocity="10"/>
    <dynamics damping="0.5" friction="0.0"/>
  </joint>
  <joint name="j_tibia_lf" type="revolute">
    <parent link="thigh_lf"/>
    <child link="tibia_lf"/>
    <!-- <origin xyz="0 ${thigh_offset_y} ${thigh_offset_z}" rpy="-1.5707 0 3.14159" /> -->
    <origin rpy="3.141592653589793 0 2.0943951023931953" xyz="0.0525 0 0"/>
    <axis xyz="0 0 -1"/>
    <limit effort="5.8" lower="-2.5" upper="2.5" velocity="10"/>
    <dynamics damping="0.5" friction="0.0"/>
  </joint>
  <joint name="j_tibia_e_lf" type="fixed">
    <parent link="tibia_lf"/>
    <child link="tibia_e_lf"/>
    <!-- <origin xyz="0 ${thigh_offset_y} ${thigh_offset_z}" rpy="-1.5707 0 3.14159" /> -->
    <origin rpy="0 0 0" xyz="-0.084 -0.05 0"/>
  </joint>
  <transmission name="t_c1_lf">
    <type>transmission_interface/SimpleTransmission</type>
    <joint name="j_c1_lf">
      <hardwareInterface>hardware_interface/EffortJointInterface</hardwareInterface>
    </joint>
    <actuator name="m_c1_lf">
      <hardwareInterface>hardware_interface/EffortJointInterface</hardwareInterface>
      <mechanicalReduction>1</mechanicalReduction>
    </actuator>
  </transmission>
  <transmission name="t_thigh_lf">
    <type>transmission_interface/SimpleTransmission</type>
    <joint name="j_thigh_lf">
      <hardwareInterface>hardware_interface/EffortJointInterface</hardwareInterface>
    </joint>
    <actuator name="m_thigh_lf">
      <hardwareInterface>hardware_interface/EffortJointInterface</hardwareInterface>
      <mechanicalReduction>1</mechanicalReduction>
    </actuator>
  </transmission>
  <transmission name="t_tibia_lf">
    <type>transmission_interface/SimpleTransmission</type>
    <joint name="j_tibia_lf">
      <hardwareInterface>hardware_interface/EffortJointInterface</hardwareInterface>
    </joint>
    <actuator name="m_tibia_lf">
      <hardwareInterface>hardware_interface/EffortJointInterface</hardwareInterface>
      <mechanicalReduction>1</mechanicalReduction>
    </actuator>
  </transmission>
  <gazebo reference="MP_BODY">
    <mu1>0.61</mu1>
    <mu2>0.61</mu2>
  </gazebo>
  <gazebo reference="c1_lf">
    <material>Gazebo/Grey</material>
    <mu1>0.61</mu1>
    <mu2>0.61</mu2>
  </gazebo>
  <gazebo reference="connect_lf">
    <mu1>0.61</mu1>
    <mu2>0.61</mu2>
  </gazebo>
  <gazebo reference="thigh_lf">
    <material>Gazebo/Grey</material>
    <mu1>0.61</mu1>
    <mu2>0.61</mu2>
  </gazebo>
  <gazebo reference="tibia_lf">
    <material>Gazebo/Grey</material>
    <mu1>0.61</mu1>
    <mu2>0.61</mu2>
  </gazebo>
  <gazebo reference="tibia_e_lf">
    <material>Gazebo/Grey</material>
    <mu1>10</mu1>
    <mu2>10</mu2>
    <kp>1000000.0</kp>
    <kd>10.0</kd>
  </gazebo>
  <!-- <gazebo reference="theta_link_${suffix}">    
    <material>Gazebo/Grey</material>
   <mu1>0.61</mu1>
    <mu2>0.61</mu2>

  </gazebo> -->
  <!-- <gazebo reference="foot_link_${suffix}">    
    <material>Gazebo/Grey</material>
    <mu1>100</mu1>
    <mu2>100</mu2>

    <kp>1000000.0</kp>
    <kd>10.0</kd>

  </gazebo> -->
  <!-- <gazebo reference="footc_${suffix}">    
    <material>Gazebo/White</material>
  </gazebo> -->
  <link name="c1_lm">
    <inertial>
      <origin rpy="0 0 0" xyz="0 0 0"/>
      <mass value="0.024357719"/>
      <inertia ixx="0.0051411124" ixy="-0.00057530255" ixz="-0.000024729049" iyy="0.0081915737" iyz="-0.000019223094" izz="0.0011379812"/>
    </inertial>
    <visual>
      <origin rpy="0 0 0" xyz="0 0.012 0"/>
      <geometry>
        <!--box size="0.045 0.022 0.0325" /-->
        <mesh filename="package://hexapod/meshes/right1_Link.STL" scale="1 1 1"/>
      </geometry>
      <material name="Grey">
        <color rgba="0.20 0.20 0.20 1.0"/>
      </material>
    </visual>
    <collision>
      <!-- <origin xyz="0 0.012 0" rpy="0 0 0"  />
      <geometry>
        <mesh filename="package://hexapod/meshes/right1_Link.STL"  scale="1 1 1"/>
      </geometry> -->
      <origin rpy="1.57 0 0" xyz="0 0.0 0"/>
      <geometry>
        <cylinder length="0.03" radius="0.01"/>
      </geometry>
    </collision>
  </link>
  <link name="connect_lm">
    <origin rpy="0 0 0" xyz="0 0 0"/>
    <inertial>
      <origin xyz="0 0 0"/>
      <mass value="0.97559947"/>
      <inertia ixx="3.1081800" ixy="-0.25460189" ixz="2.0318174" iyy="6.3787776" iyz="0.16417863" izz="5.3316425"/>
    </inertial>
  </link>
  <joint name="j_connect_lm" type="fixed">
    <parent link="MP_BODY"/>
    <child link="connect_lm"/>
    <origin rpy="0 -3.141592653589793 4.71238898038469" xyz="-0.038 0.0  0.02"/>
  </joint>
  <link name="thigh_lm">
    <inertial>
      <origin rpy="0 1.57 0" xyz="0 0.0 0"/>
      <mass value="0.024357719"/>
      <inertia ixx="0.0051411124" ixy="-0.00057530255" ixz="-0.000024729049" iyy="0.0081915737" iyz="-0.000019223094" izz="0.0011379812"/>
    </inertial>
    <visual>
      <origin rpy="0 0 0" xyz="0 0 -0.004"/>
      <geometry>
        <!--box size="0.045 0.022 0.0325" /-->
        <mesh filename="package://hexapod/meshes/LinkThigh.STL" scale="1 1 1"/>
      </geometry>
      <material name="Grey">
        <color rgba="0.20 0.20 0.20 1.0"/>
      </material>
    </visual>
    <collision>
      <origin rpy="0 1.57 0" xyz="0 0.0 0"/>
      <geometry>
        <cylinder length="0.05" radius="0.01"/>
      </geometry>
    </collision>
  </link>
  <link name="tibia_lm">
    <inertial>
      <origin rpy="0 1.57 0.524" xyz="-0.027 -0.017 0"/>
      <mass value="0.002"/>
      <inertia ixx="0.0000024045" ixy="0" ixz="0" iyy="0.0000024045" iyz="0" izz="0.000000009"/>
    </inertial>
    <visual>
      <origin rpy="0 0 0" xyz="0 0 0"/>
      <geometry>
        <!--box size="0.045 0.022 0.0325" /-->
        <!-- <mesh filename="package://robot_envs/hexapod/robot/meshes/LinkTibia.STL"  scale="1 1 1"/> -->
        <mesh filename="package://hexapod/meshes/NewTibia.STL" scale="0.001 0.001 0.001"/>
      </geometry>
      <material name="Grey">
        <color rgba="0.20 0.20 0.20 1.0"/>
      </material>
    </visual>
    <collision>
      <origin rpy="0 1.57 0.524" xyz="-0.027 -0.017 0"/>
      <geometry>
        <cylinder length="0.12" radius="0.003"/>
      </geometry>
    </collision>
  </link>
  <!-- <link name="tibia_e_${suffix}">

      <visual><geometry><sphere radius="0.003"/></geometry></visual>
      <collision><geometry><sphere radius="0.005"/></geometry></collision>
      <inertial>
          <origin xyz="0 0 0" rpy="0 0 0"/>
          <mass value="0.001"/>
          <inertia ixx="0.1" ixy="0.0" ixz="0.0" iyy="0.1"  iyz="0.0" izz="0.1"/>
      </inertial>
  </link> -->
  <link name="tibia_e_lm">
    <visual>
      <origin rpy="0 0 0" xyz="0 0 0"/>
      <geometry>
        <sphere radius=".006"/>
      </geometry>
    </visual>
    <collision>
      <geometry>
        <sphere radius=".006"/>
      </geometry>
    </collision>
    <inertial>
      <origin rpy="0 0 0" xyz="0 0 0"/>
      <mass value="0.01"/>
      <inertia ixx="0.00144" ixy="0.0" ixz="0.0" iyy="0.00144" iyz="0.0" izz="0.00144"/>
    </inertial>
  </link>
  <!-- here are an edit including a ball joint -->
  <joint name="j_c1_lm" type="revolute">
    <parent link="connect_lm"/>
    <child link="c1_lm"/>
    <origin rpy="0 3.141592653589793 3.141592653589793" xyz="0 0 0"/>
    <axis xyz="0 0 -1"/>
    <limit effort="5.8" lower="-2.6179939" upper="2.6179939" velocity="10"/>
    <dynamics damping="0.5" friction="0.0"/>
  </joint>
  <joint name="j_thigh_lm" type="revolute">
    <parent link="c1_lm"/>
    <child link="thigh_lm"/>
    <origin rpy="1.5707963267948966 -0.2617993877991494 1.5707963267948966" xyz="0 0.053 0"/>
    <axis xyz="0 0 1"/>
    <limit effort="5.8" lower="-2.6179939" upper="2.6179939" velocity="10"/>
    <dynamics damping="0.5" friction="0.0"/>
  </joint>
  <joint name="j_tibia_lm" type="revolute">
    <parent link="thigh_lm"/>
    <child link="tibia_lm"/>
    <!-- <origin xyz="0 ${thigh_offset_y} ${thigh_offset_z}" rpy="-1.5707 0 3.14159" /> -->
    <origin rpy="3.141592653589793 0 2.0943951023931953" xyz="0.0525 0 0"/>
    <axis xyz="0 0 -1"/>
    <limit effort="5.8" lower="-2.5" upper="2.5" velocity="10"/>
    <dynamics damping="0.5" friction="0.0"/>
  </joint>
  <joint name="j_tibia_e_lm" type="fixed">
    <parent link="tibia_lm"/>
    <child link="tibia_e_lm"/>
    <!-- <origin xyz="0 ${thigh_offset_y} ${thigh_offset_z}" rpy="-1.5707 0 3.14159" /> -->
    <origin rpy="0 0 0" xyz="-0.084 -0.05 0"/>
  </joint>
  <transmission name="t_c1_lm">
    <type>transmission_interface/SimpleTransmission</type>
    <joint name="j_c1_lm">
      <hardwareInterface>hardware_interface/EffortJointInterface</hardwareInterface>
    </joint>
    <actuator name="m_c1_lm">
      <hardwareInterface>hardware_interface/EffortJointInterface</hardwareInterface>
      <mechanicalReduction>1</mechanicalReduction>
    </actuator>
  </transmission>
  <transmission name="t_thigh_lm">
    <type>transmission_interface/SimpleTransmission</type>
    <joint name="j_thigh_lm">
      <hardwareInterface>hardware_interface/EffortJointInterface</hardwareInterface>
    </joint>
    <actuator name="m_thigh_lm">
      <hardwareInterface>hardware_interface/EffortJointInterface</hardwareInterface>
      <mechanicalReduction>1</mechanicalReduction>
    </actuator>
  </transmission>
  <transmission name="t_tibia_lm">
    <type>transmission_interface/SimpleTransmission</type>
    <joint name="j_tibia_lm">
      <hardwareInterface>hardware_interface/EffortJointInterface</hardwareInterface>
    </joint>
    <actuator name="m_tibia_lm">
      <hardwareInterface>hardware_interface/EffortJointInterface</hardwareInterface>
      <mechanicalReduction>1</mechanicalReduction>
    </actuator>
  </transmission>
  <gazebo reference="MP_BODY">
    <mu1>0.61</mu1>
    <mu2>0.61</mu2>
  </gazebo>
  <gazebo reference="c1_lm">
    <material>Gazebo/Grey</material>
    <mu1>0.61</mu1>
    <mu2>0.61</mu2>
  </gazebo>
  <gazebo reference="connect_lm">
    <mu1>0.61</mu1>
    <mu2>0.61</mu2>
  </gazebo>
  <gazebo reference="thigh_lm">
    <material>Gazebo/Grey</material>
    <mu1>0.61</mu1>
    <mu2>0.61</mu2>
  </gazebo>
  <gazebo reference="tibia_lm">
    <material>Gazebo/Grey</material>
    <mu1>0.61</mu1>
    <mu2>0.61</mu2>
  </gazebo>
  <gazebo reference="tibia_e_lm">
    <material>Gazebo/Grey</material>
    <mu1>10</mu1>
    <mu2>10</mu2>
    <kp>1000000.0</kp>
    <kd>10.0</kd>
  </gazebo>
  <!-- <gazebo reference="theta_link_${suffix}">    
    <material>Gazebo/Grey</material>
   <mu1>0.61</mu1>
    <mu2>0.61</mu2>

  </gazebo> -->
  <!-- <gazebo reference="foot_link_${suffix}">    
    <material>Gazebo/Grey</material>
    <mu1>100</mu1>
    <mu2>100</mu2>

    <kp>1000000.0</kp>
    <kd>10.0</kd>

  </gazebo> -->
  <!-- <gazebo reference="footc_${suffix}">    
    <material>Gazebo/White</material>
  </gazebo> -->
  <link name="c1_lr">
    <inertial>
      <origin rpy="0 0 0" xyz="0 0 0"/>
      <mass value="0.024357719"/>
      <inertia ixx="0.0051411124" ixy="-0.00057530255" ixz="-0.000024729049" iyy="0.0081915737" iyz="-0.000019223094" izz="0.0011379812"/>
    </inertial>
    <visual>
      <origin rpy="0 0 0" xyz="0 0.012 0"/>
      <geometry>
        <!--box size="0.045 0.022 0.0325" /-->
        <mesh filename="package://hexapod/meshes/right1_Link.STL" scale="1 1 1"/>
      </geometry>
      <material name="Grey">
        <color rgba="0.20 0.20 0.20 1.0"/>
      </material>
    </visual>
    <collision>
      <!-- <origin xyz="0 0.012 0" rpy="0 0 0"  />
      <geometry>
        <mesh filename="package://hexapod/meshes/right1_Link.STL"  scale="1 1 1"/>
      </geometry> -->
      <origin rpy="1.57 0 0" xyz="0 0.0 0"/>
      <geometry>
        <cylinder length="0.03" radius="0.01"/>
      </geometry>
    </collision>
  </link>
  <link name="connect_lr">
    <origin rpy="0 0 0" xyz="0 0 0"/>
    <inertial>
      <origin xyz="0 0 0"/>
      <mass value="0.97559947"/>
      <inertia ixx="3.1081800" ixy="-0.25460189" ixz="2.0318174" iyy="6.3787776" iyz="0.16417863" izz="5.3316425"/>
    </inertial>
  </link>
  <joint name="j_connect_lr" type="fixed">
    <parent link="MP_BODY"/>
    <child link="connect_lr"/>
    <origin rpy="0 -3.141592653589793 4.71238898038469" xyz="-0.038 -0.046  0.02"/>
  </joint>
  <link name="thigh_lr">
    <inertial>
      <origin rpy="0 1.57 0" xyz="0 0.0 0"/>
      <mass value="0.024357719"/>
      <inertia ixx="0.0051411124" ixy="-0.00057530255" ixz="-0.000024729049" iyy="0.0081915737" iyz="-0.000019223094" izz="0.0011379812"/>
    </inertial>
    <visual>
      <origin rpy="0 0 0" xyz="0 0 -0.004"/>
      <geometry>
        <!--box size="0.045 0.022 0.0325" /-->
        <mesh filename="package://hexapod/meshes/LinkThigh.STL" scale="1 1 1"/>
      </geometry>
      <material name="Grey">
        <color rgba="0.20 0.20 0.20 1.0"/>
      </material>
    </visual>
    <collision>
      <origin rpy="0 1.57 0" xyz="0 0.0 0"/>
      <geometry>
        <cylinder length="0.05" radius="0.01"/>
      </geometry>
    </collision>
  </link>
  <link name="tibia_lr">
    <inertial>
      <origin rpy="0 1.57 0.524" xyz="-0.027 -0.017 0"/>
      <mass value="0.002"/>
      <inertia ixx="0.0000024045" ixy="0" ixz="0" iyy="0.0000024045" iyz="0" izz="0.000000009"/>
    </inertial>
    <visual>
      <origin rpy="0 0 0" xyz="0 0 0"/>
      <geometry>
        <!--box size="0.045 0.022 0.0325" /-->
        <!-- <mesh filename="package://robot_envs/hexapod/robot/meshes/LinkTibia.STL"  scale="1 1 1"/> -->
        <mesh filename="package://hexapod/meshes/NewTibia.STL" scale="0.001 0.001 0.001"/>
      </geometry>
      <material name="Grey">
        <color rgba="0.20 0.20 0.20 1.0"/>
      </material>
    </visual>
    <collision>
      <origin rpy="0 1.57 0.524" xyz="-0.027 -0.017 0"/>
      <geometry>
        <cylinder length="0.12" radius="0.003"/>
      </geometry>
    </collision>
  </link>
  <!-- <link name="tibia_e_${suffix}">

      <visual><geometry><sphere radius="0.003"/></geometry></visual>
      <collision><geometry><sphere radius="0.005"/></geometry></collision>
      <inertial>
          <origin xyz="0 0 0" rpy="0 0 0"/>
          <mass value="0.001"/>
          <inertia ixx="0.1" ixy="0.0" ixz="0.0" iyy="0.1"  iyz="0.0" izz="0.1"/>
      </inertial>
  </link> -->
  <link name="tibia_e_lr">
    <visual>
      <origin rpy="0 0 0" xyz="0 0 0"/>
      <geometry>
        <sphere radius=".006"/>
      </geometry>
    </visual>
    <collision>
      <geometry>
        <sphere radius=".006"/>
      </geometry>
    </collision>
    <inertial>
      <origin rpy="0 0 0" xyz="0 0 0"/>
      <mass value="0.01"/>
      <inertia ixx="0.00144" ixy="0.0" ixz="0.0" iyy="0.00144" iyz="0.0" izz="0.00144"/>
    </inertial>
  </link>
  <!-- here are an edit including a ball joint -->
  <joint name="j_c1_lr" type="revolute">
    <parent link="connect_lr"/>
    <child link="c1_lr"/>
    <origin rpy="0 3.141592653589793 2.0943951023931957" xyz="0 0 0"/>
    <axis xyz="0 0 -1"/>
    <limit effort="5.8" lower="-2.6179939" upper="2.6179939" velocity="10"/>
    <dynamics damping="0.5" friction="0.0"/>
  </joint>
  <joint name="j_thigh_lr" type="revolute">
    <parent link="c1_lr"/>
    <child link="thigh_lr"/>
    <origin rpy="1.5707963267948966 -0.2617993877991494 1.5707963267948966" xyz="0 0.053 0"/>
    <axis xyz="0 0 1"/>
    <limit effort="5.8" lower="-2.6179939" upper="2.6179939" velocity="10"/>
    <dynamics damping="0.5" friction="0.0"/>
  </joint>
  <joint name="j_tibia_lr" type="revolute">
    <parent link="thigh_lr"/>
    <child link="tibia_lr"/>
    <!-- <origin xyz="0 ${thigh_offset_y} ${thigh_offset_z}" rpy="-1.5707 0 3.14159" /> -->
    <origin rpy="3.141592653589793 0 2.0943951023931953" xyz="0.0525 0 0"/>
    <axis xyz="0 0 -1"/>
    <limit effort="5.8" lower="-2.5" upper="2.5" velocity="10"/>
    <dynamics damping="0.5" friction="0.0"/>
  </joint>
  <joint name="j_tibia_e_lr" type="fixed">
    <parent link="tibia_lr"/>
    <child link="tibia_e_lr"/>
    <!-- <origin xyz="0 ${thigh_offset_y} ${thigh_offset_z}" rpy="-1.5707 0 3.14159" /> -->
    <origin rpy="0 0 0" xyz="-0.084 -0.05 0"/>
  </joint>
  <transmission name="t_c1_lr">
    <type>transmission_interface/SimpleTransmission</type>
    <joint name="j_c1_lr">
      <hardwareInterface>hardware_interface/EffortJointInterface</hardwareInterface>
    </joint>
    <actuator name="m_c1_lr">
      <hardwareInterface>hardware_interface/EffortJointInterface</hardwareInterface>
      <mechanicalReduction>1</mechanicalReduction>
    </actuator>
  </transmission>
  <transmission name="t_thigh_lr">
    <type>transmission_interface/SimpleTransmission</type>
    <joint name="j_thigh_lr">
      <hardwareInterface>hardware_interface/EffortJointInterface</hardwareInterface>
    </joint>
    <actuator name="m_thigh_lr">
      <hardwareInterface>hardware_interface/EffortJointInterface</hardwareInterface>
      <mechanicalReduction>1</mechanicalReduction>
    </actuator>
  </transmission>
  <transmission name="t_tibia_lr">
    <type>transmission_interface/SimpleTransmission</type>
    <joint name="j_tibia_lr">
      <hardwareInterface>hardware_interface/EffortJointInterface</hardwareInterface>
    </joint>
    <actuator name="m_tibia_lr">
      <hardwareInterface>hardware_interface/EffortJointInterface</hardwareInterface>
      <mechanicalReduction>1</mechanicalReduction>
    </actuator>
  </transmission>
  <gazebo reference="MP_BODY">
    <mu1>0.61</mu1>
    <mu2>0.61</mu2>
  </gazebo>
  <gazebo reference="c1_lr">
    <material>Gazebo/Grey</material>
    <mu1>0.61</mu1>
    <mu2>0.61</mu2>
  </gazebo>
  <gazebo reference="connect_lr">
    <mu1>0.61</mu1>
    <mu2>0.61</mu2>
  </gazebo>
  <gazebo reference="thigh_lr">
    <material>Gazebo/Grey</material>
    <mu1>0.61</mu1>
    <mu2>0.61</mu2>
  </gazebo>
  <gazebo reference="tibia_lr">
    <material>Gazebo/Grey</material>
    <mu1>0.61</mu1>
    <mu2>0.61</mu2>
  </gazebo>
  <gazebo reference="tibia_e_lr">
    <material>Gazebo/Grey</material>
    <mu1>10</mu1>
    <mu2>10</mu2>
    <kp>1000000.0</kp>
    <kd>10.0</kd>
  </gazebo>
  <!-- <gazebo reference="theta_link_${suffix}">    
    <material>Gazebo/Grey</material>
   <mu1>0.61</mu1>
    <mu2>0.61</mu2>

  </gazebo> -->
  <!-- <gazebo reference="foot_link_${suffix}">    
    <material>Gazebo/Grey</material>
    <mu1>100</mu1>
    <mu2>100</mu2>

    <kp>1000000.0</kp>
    <kd>10.0</kd>

  </gazebo> -->
  <!-- <gazebo reference="footc_${suffix}">    
    <material>Gazebo/White</material>
  </gazebo> -->
  <gazebo>
    <plugin filename="libgazebo_ros_control.so" name="gazebo_ros_control">
      <robotNamespace>/hexapod</robotNamespace>
    </plugin>
    <plugin filename="libgazebo_ros_p3d.so" name="p3d_base_controller">
      <alwaysOn>true</alwaysOn>
      <updateRate>50.0</updateRate>
      <bodyName>base_link</bodyName>
      <topicName>ground_truth/state</topicName>
      <gaussianNoise>0.0</gaussianNoise>
      <frameName>world</frameName>
      <xyzOffsets>0 0 0</xyzOffsets>
      <rpyOffsets>0 0 0</rpyOffsets>
    </plugin>
  </gazebo>
</robot>

